<?xml version="1.0" encoding="UTF-8"?>
<!-- Generated by org.testng.reporters.JUnitXMLReporter -->
<testsuite hostname="DESKTOP-V7HIM83" ignored="0" name="Test" tests="4" failures="1" timestamp="2022-03-29T22:39:32 IST" time="95.04" errors="0">
  <testcase name="test" time="0.042" classname="testclasses.Test1"/>
  <testcase name="verifyUserLogin" time="32.468" classname="testclasses.Test1"/>
  <testcase name="verifyUserCanAddNewAddress" time="19.517" classname="testclasses.Test1"/>
  <testcase name="verifyUserCanAddNewAddress" time="5.259" classname="testclasses.Test1">
    <failure type="java.lang.AssertionError" message="expected [5] but found [4]">
      <![CDATA[java.lang.AssertionError: expected [5] but found [4]
at testclasses.Test1.verifyUserCanAddNewAddress(Test1.java:162)
at java.util.ArrayList.forEach(Unknown Source)
at java.util.concurrent.FutureTask.run(Unknown Source)
at java.util.concurrent.ThreadPoolExecutor.runWorker(Unknown Source)
at java.util.concurrent.ThreadPoolExecutor$Worker.run(Unknown Source)
at java.lang.Thread.run(Unknown Source)
... Removed 24 stack frames]]>
    </failure>
  </testcase> <!-- verifyUserCanAddNewAddress -->
</testsuite> <!-- Test -->
