<?xml version="1.0" encoding="UTF-8"?>
<!-- Generated by org.testng.reporters.JUnitReportReporter -->
<testsuite skipped="0" hostname="DESKTOP-V7HIM83" name="testclasses.Test1" tests="4" failures="1" timestamp="2022-03-29T22:39:33 IST" time="58.701" errors="0">
  <testcase name="verifyUserLogin" time="33.478" classname="testclasses.Test1"/>
  <system-out>
    <![CDATA[Enter email
Enter password
submit button
Test 1 is passed]]>
  </system-out>
  <testcase name="test" time="0.421" classname="testclasses.Test1"/>
  <system-out>
    <![CDATA[Test1 is passed]]>
  </system-out>
  <testcase name="verifyUserCanAddNewAddress" time="5.272" classname="testclasses.Test1">
    <failure type="java.lang.AssertionError" message="expected [5] but found [4]">
      <![CDATA[java.lang.AssertionError: expected [5] but found [4]
at org.testng.Assert.fail(Assert.java:110)
at org.testng.Assert.failNotEquals(Assert.java:1413)
at org.testng.Assert.assertEqualsImpl(Assert.java:149)
at org.testng.Assert.assertEquals(Assert.java:131)
at org.testng.Assert.assertEquals(Assert.java:1240)
at org.testng.Assert.assertEquals(Assert.java:1274)
at testclasses.Test1.verifyUserCanAddNewAddress(Test1.java:162)
at sun.reflect.NativeMethodAccessorImpl.invoke0(Native Method)
at sun.reflect.NativeMethodAccessorImpl.invoke(Unknown Source)
at sun.reflect.DelegatingMethodAccessorImpl.invoke(Unknown Source)
at java.lang.reflect.Method.invoke(Unknown Source)
at org.testng.internal.invokers.MethodInvocationHelper.invokeMethod(MethodInvocationHelper.java:135)
at org.testng.internal.invokers.TestInvoker.invokeMethod(TestInvoker.java:673)
at org.testng.internal.invokers.TestInvoker.invokeTestMethod(TestInvoker.java:220)
at org.testng.internal.invokers.MethodRunner.runInSequence(MethodRunner.java:50)
at org.testng.internal.invokers.TestInvoker$MethodInvocationAgent.invoke(TestInvoker.java:945)
at org.testng.internal.invokers.TestInvoker.invokeTestMethods(TestInvoker.java:193)
at org.testng.internal.invokers.TestMethodWorker.invokeTestMethods(TestMethodWorker.java:146)
at org.testng.internal.invokers.TestMethodWorker.run(TestMethodWorker.java:128)
at java.util.ArrayList.forEach(Unknown Source)
at org.testng.TestRunner.privateRun(TestRunner.java:808)
at org.testng.TestRunner.run(TestRunner.java:603)
at org.testng.SuiteRunner.runTest(SuiteRunner.java:429)
at org.testng.SuiteRunner.access$000(SuiteRunner.java:32)
at org.testng.SuiteRunner$SuiteWorker.run(SuiteRunner.java:467)
at org.testng.internal.thread.ThreadUtil.lambda$execute$0(ThreadUtil.java:58)
at java.util.concurrent.FutureTask.run(Unknown Source)
at java.util.concurrent.ThreadPoolExecutor.runWorker(Unknown Source)
at java.util.concurrent.ThreadPoolExecutor$Worker.run(Unknown Source)
at java.lang.Thread.run(Unknown Source)
]]>
    </failure>
  </testcase> <!-- verifyUserCanAddNewAddress -->
  <system-out/>
  <testcase name="verifyUserCanAddNewAddress" time="19.530" classname="testclasses.Test1"/>
  <system-out/>
</testsuite> <!-- testclasses.Test1 -->
